from log_utility import log_error
log_error("Логируем тестовую ошибку")